Workbook

Sheet RAW_DATA
A1: Authors | B1: Title | C1: Year | D1: Source title | E1: Volume | F1: Issue | G1: Art. No. | H1: Page start | I1: Page end | J1: Cited by | K1: DOI | L1: Link | M1: Document Type | N1: Publication Stage | O1: Open Access | P1: Source | Q1: EID | R1: [Autofills] NOT IN PAPERS | S1: [Autofills] Is Duplicate?
A2: Stepin I.; Alonso J.M.; Catala A.; Pereira-Farina M. | B2: A Survey of Contrastive and Counterfactual Explanation Generation Methods for Explainable Artificial Intelligence | C2: 2021 | D2: IEEE Access | E2: 9 | G2: 9321372 | H2: 11974 | I2: 12001 | J2: 340 | K2: 10.1109/ACCESS.2021.3051315 | L2: https://www.scopus.com/pages/publications/85099601493?origin=resultslist | M2: Review | N2: Final | O2: All Open Access; Gold Open Access; Green Open Access | P2: Scopus | Q2: 2-s2.0-85099601493 | R2: =COUNTIF( Papers!G:G, RAW_DATA!Q2 ) = 0 -> FALSE | S2: =(COUNTIF(B:B, B2) > 1 ) -> FALSE
A3: Nazar M.; Alam M.M.; Yafi E.; Su'Ud M.M. | B3: A Systematic Review of Human-Computer Interaction and Explainable Artificial Intelligence in Healthcare with Artificial Intelligence Techniques | C3: 2021 | D3: IEEE Access | E3: 9 | H3: 153316 | I3: 153348 | J3: 263 | K3: 10.1109/ACCESS.2021.3127881 | L3: https://www.scopus.com/pages/publications/85119430656?origin=resultslist | M3: Review | N3: Final | O3: All Open Access; Gold Open Access; Green Open Access | P3: Scopus | Q3: 2-s2.0-85119430656 | R3: =COUNTIF( Papers!G:G, RAW_DATA!Q3 ) = 0 -> FALSE | S3: =(COUNTIF(B:B, B3) > 1 ) -> FALSE
A4: Young A.T.; Amara D.; Bhattacharya A.; Wei M.L. | B4: Patient and general public attitudes towards clinical artificial intelligence: a mixed methods systematic review | C4: 2021 | D4: The Lancet Digital Health | E4: 3 | F4: 9 | H4: e599 | I4: e611 | J4: 264 | K4: 10.1016/S2589-7500(21)00132-1 | L4: https://www.scopus.com/pages/publications/85115041953?origin=resultslist | M4: Review | N4: Final | O4: All Open Access; Gold Open Access | P4: Scopus | Q4: 2-s2.0-85115041953 | R4: =COUNTIF( Papers!G:G, RAW_DATA!Q4 ) = 0 -> FALSE | S4: =(COUNTIF(B:B, B4) > 1 ) -> FALSE
A5: Rashid A.B.; Kausik M.A.K. | B5: AI revolutionizing industries worldwide: A comprehensive overview of its diverse applications | C5: 2024 | D5: Hybrid Advances | E5: 7 | G5: 100277 | J5: 486 | K5: 10.1016/j.hybadv.2024.100277 | L5: https://www.scopus.com/pages/publications/85204730281?origin=resultslist | M5: Review | N5: Final | O5: All Open Access; Gold Open Access; Green Open Access | P5: Scopus | Q5: 2-s2.0-85204730281 | R5: =COUNTIF( Papers!G:G, RAW_DATA!Q5 ) = 0 -> FALSE | S5: =(COUNTIF(B:B, B5) > 1 ) -> FALSE
A6: Tong S.; Jia N.; Luo X.; Fang Z. | B6: The Janus face of artificial intelligence feedback: Deployment versus disclosure effects on employee performance | C6: 2021 | D6: Strategic Management Journal | E6: 42 | F6: 9 | H6: 1600 | I6: 1631 | J6: 371 | K6: 10.1002/smj.3322 | L6: https://www.scopus.com/pages/publications/85109705359?origin=resultslist | M6: Article | N6: Final | O6: All Open Access; Hybrid Gold Open Access | P6: Scopus | Q6: 2-s2.0-85109705359 | R6: =COUNTIF( Papers!G:G, RAW_DATA!Q6 ) = 0 -> FALSE | S6: =(COUNTIF(B:B, B6) > 1 ) -> FALSE
A7: Zhang T.; Tao D.; Qu X.; Zhang X.; Zeng J.; Zhu H.; Zhu H. | B7: Automated vehicle acceptance in China: Social influence and initial trust are key determinants | C7: 2020 | D7: Transportation Research Part C: Emerging Technologies | E7: 112 | H7: 220 | I7: 233 | J7: 398 | K7: 10.1016/j.trc.2020.01.027 | L7: https://www.scopus.com/pages/publications/85078934939?origin=resultslist | M7: Article | N7: Final | P7: Scopus | Q7: 2-s2.0-85078934939 | R7: =COUNTIF( Papers!G:G, RAW_DATA!Q7 ) = 0 -> FALSE | S7: =(COUNTIF(B:B, B7) > 1 ) -> FALSE
A8: Tussyadiah I.P.; Zach F.J.; Wang J. | B8: Do travelers trust intelligent service robots? | C8: 2020 | D8: Annals of Tourism Research | E8: 81 | G8: 102886 | J8: 280 | K8: 10.1016/j.annals.2020.102886 | L8: https://www.scopus.com/pages/publications/85079861440?origin=resultslist | M8: Article | N8: Final | P8: Scopus | Q8: 2-s2.0-85079861440 | R8: =COUNTIF( Papers!G:G, RAW_DATA!Q8 ) = 0 -> FALSE | S8: =(COUNTIF(B:B, B8) > 1 ) -> FALSE
A9: Rudin C.; Chen C.; Chen Z.; Huang H.; Semenova L.; Zhong C. | B9: Interpretable machine learning: Fundamental principles and 10 grand challenges | C9: 2022 | D9: Statistics Surveys | E9: 16 | H9: 1 | I9: 85 | J9: 684 | K9: 10.1214/21-SS133 | L9: https://www.scopus.com/pages/publications/85125573696?origin=resultslist | M9: Article | N9: Final | O9: All Open Access; Gold Open Access | P9: Scopus | Q9: 2-s2.0-85125573696 | R9: =COUNTIF( Papers!G:G, RAW_DATA!Q9 ) = 0 -> FALSE | S9: =(COUNTIF(B:B, B9) > 1 ) -> FALSE
A10: Asan O.; Bayrak A.E.; Choudhury A. | B10: Artificial Intelligence and Human Trust in Healthcare: Focus on Clinicians | C10: 2020 | D10: Journal of Medical Internet Research | E10: 22 | F10: 6 | G10: e15154 | J10: 604 | K10: 10.2196/15154 | L10: https://www.scopus.com/pages/publications/85086727009?origin=resultslist | M10: Review | N10: Final | O10: All Open Access; Gold Open Access; Green Open Access | P10: Scopus | Q10: 2-s2.0-85086727009 | R10: =COUNTIF( Papers!G:G, RAW_DATA!Q10 ) = 0 -> FALSE | S10: =(COUNTIF(B:B, B10) > 1 ) -> FALSE
A11: Hergeth S.; Lorenz L.; Vilimek R.; Krems J.F. | B11: Keep Your Scanners Peeled: Gaze Behavior as a Measure of Automation Trust during Highly Automated Driving | C11: 2016 | D11: Human Factors | E11: 58 | F11: 3 | H11: 509 | I11: 519 | J11: 311 | K11: 10.1177/0018720815625744 | L11: https://www.scopus.com/pages/publications/84962910809?origin=resultslist | M11: Article | N11: Final | P11: Scopus | Q11: 2-s2.0-84962910809 | R11: =COUNTIF( Papers!G:G, RAW_DATA!Q11 ) = 0 -> FALSE | S11: =(COUNTIF(B:B, B11) > 1 ) -> FALSE
A12: Honig S.; Oron-Gilad T. | B12: Understanding and resolving failures in human-robot interaction: Literature review and model development | C12: 2018 | D12: Frontiers in Psychology | E12: 9 | F12: JUN | G12: 861 | J12: 308 | K12: 10.3389/fpsyg.2018.00861 | L12: https://www.scopus.com/pages/publications/85048531596?origin=resultslist | M12: Review | N12: Final | O12: All Open Access; Gold Open Access; Green Open Access | P12: Scopus | Q12: 2-s2.0-85048531596 | R12: =COUNTIF( Papers!G:G, RAW_DATA!Q12 ) = 0 -> FALSE | S12: =(COUNTIF(B:B, B12) > 1 ) -> FALSE
A13: Carsten O.; Martens M.H. | B13: How can humans understand their automated cars? HMI principles, problems and solutions | C13: 2019 | D13: Cognition, Technology and Work | E13: 21 | F13: 1 | H13: 3 | I13: 20 | J13: 233 | K13: 10.1007/s10111-018-0484-0 | L13: https://www.scopus.com/pages/publications/85046726952?origin=resultslist | M13: Article | N13: Final | O13: All Open Access; Green Open Access; Hybrid Gold Open Access | P13: Scopus | Q13: 2-s2.0-85046726952 | R13: =COUNTIF( Papers!G:G, RAW_DATA!Q13 ) = 0 -> FALSE | S13: =(COUNTIF(B:B, B13) > 1 ) -> FALSE
A14: Vilone G.; Longo L. | B14: Notions of explainability and evaluation approaches for explainable artificial intelligence | C14: 2021 | D14: Information Fusion | E14: 76 | H14: 89 | I14: 106 | J14: 510 | K14: 10.1016/j.inffus.2021.05.009 | L14: https://www.scopus.com/pages/publications/85107637272?origin=resultslist | M14: Article | N14: Final | O14: All Open Access; Green Open Access; Hybrid Gold Open Access | P14: Scopus | Q14: 2-s2.0-85107637272 | R14: =COUNTIF( Papers!G:G, RAW_DATA!Q14 ) = 0 -> FALSE | S14: =(COUNTIF(B:B, B14) > 1 ) -> FALSE
A15: Pereira V.; Hadjielias E.; Christofi M.; Vrontis D. | B15: A systematic literature review on the impact of artificial intelligence on workplace outcomes: A multi-process perspective | C15: 2023 | D15: Human Resource Management Review | E15: 33 | F15: 1 | G15: 100857 | J15: 384 | K15: 10.1016/j.hrmr.2021.100857 | L15: https://www.scopus.com/pages/publications/85114687655?origin=resultslist | M15: Article | N15: Final | O15: All Open Access; Green Open Access | P15: Scopus | Q15: 2-s2.0-85114687655 | R15: =COUNTIF( Papers!G:G, RAW_DATA!Q15 ) = 0 -> FALSE | S15: =(COUNTIF(B:B, B15) > 1 ) -> FALSE
A16: Langer M.; Oster D.; Speith T.; Hermanns H.; Kästner L.; Schmidt E.; Sesing A.; Baum K. | B16: What do we want from Explainable Artificial Intelligence (XAI)? – A stakeholder perspective on XAI and a conceptual model guiding interdisciplinary XAI research | C16: 2021 | D16: Artificial Intelligence | E16: 296 | G16: 103473 | J16: 541 | K16: 10.1016/j.artint.2021.103473 | L16: https://www.scopus.com/pages/publications/85101531468?origin=resultslist | M16: Article | N16: Final | O16: All Open Access; Bronze Open Access; Green Open Access | P16: Scopus | Q16: 2-s2.0-85101531468 | R16: =COUNTIF( Papers!G:G, RAW_DATA!Q16 ) = 0 -> FALSE | S16: =(COUNTIF(B:B, B16) > 1 ) -> FALSE
A17: Chalmers D.; MacKenzie N.G.; Carter S. | B17: Artificial Intelligence and Entrepreneurship: Implications for Venture Creation in the Fourth Industrial Revolution | C17: 2021 | D17: Entrepreneurship: Theory and Practice | E17: 45 | F17: 5 | H17: 1028 | I17: 1053 | J17: 397 | K17: 10.1177/1042258720934581 | L17: https://www.scopus.com/pages/publications/85087930775?origin=resultslist | M17: Article | N17: Final | O17: All Open Access; Bronze Open Access; Green Open Access | P17: Scopus | Q17: 2-s2.0-85087930775 | R17: =COUNTIF( Papers!G:G, RAW_DATA!Q17 ) = 0 -> FALSE | S17: =(COUNTIF(B:B, B17) > 1 ) -> FALSE
A18: Chowdhury S.; Budhwar P.; Dey P.K.; Joel-Edgar S.; Abadie A. | B18: AI-employee collaboration and business performance: Integrating knowledge-based view, socio-technical systems and organisational socialisation framework | C18: 2022 | D18: Journal of Business Research | E18: 144 | H18: 31 | I18: 49 | J18: 365 | K18: 10.1016/j.jbusres.2022.01.069 | L18: https://www.scopus.com/pages/publications/85124046364?origin=resultslist | M18: Article | N18: Final | P18: Scopus | Q18: 2-s2.0-85124046364 | R18: =COUNTIF( Papers!G:G, RAW_DATA!Q18 ) = 0 -> FALSE | S18: =(COUNTIF(B:B, B18) > 1 ) -> FALSE
A19: Dellermann D.; Ebel P.; Söllner M.; Leimeister J.M. | B19: Hybrid Intelligence | C19: 2019 | D19: Business and Information Systems Engineering | E19: 61 | F19: 5 | H19: 637 | I19: 643 | J19: 581 | K19: 10.1007/s12599-019-00595-2 | L19: https://www.scopus.com/pages/publications/85069455009?origin=resultslist | M19: Article | N19: Final | O19: All Open Access; Green Open Access | P19: Scopus | Q19: 2-s2.0-85069455009 | R19: =COUNTIF( Papers!G:G, RAW_DATA!Q19 ) = 0 -> FALSE | S19: =(COUNTIF(B:B, B19) > 1 ) -> FALSE
A20: Man Tang P.; Koopman J.; McClean S.T.; Zhang J.H.; Hon Li C.; de Cremer D.; Lu Y.; Stewart Ng C.T. | B20: WHEN CONSCIENTIOUS EMPLOYEES MEET INTELLIGENT MACHINES: AN INTEGRATIVE APPROACH INSPIRED BY COMPLEMENTARITY THEORY AND ROLE THEORY | C20: 2022 | D20: Academy of Management Journal | E20: 65 | F20: 3 | H20: 1019 | I20: 1054 | J20: 230 | K20: 10.5465/AMJ.2020.1516 | L20: https://www.scopus.com/pages/publications/85135124659?origin=resultslist | M20: Article | N20: Final | P20: Scopus | Q20: 2-s2.0-85135124659 | R20: =COUNTIF( Papers!G:G, RAW_DATA!Q20 ) = 0 -> FALSE | S20: =(COUNTIF(B:B, B20) > 1 ) -> FALSE
A21: Mirbabaie M.; Brünker F.; Möllmann Frick N.R.J.; Stieglitz S. | B21: The rise of artificial intelligence – understanding the AI identity threat at the workplace | C21: 2022 | D21: Electronic Markets | E21: 32 | F21: 1 | H21: 73 | I21: 99 | J21: 259 | K21: 10.1007/s12525-021-00496-x | L21: https://www.scopus.com/pages/publications/85116415765?origin=resultslist | M21: Article | N21: Final | O21: All Open Access; Green Open Access; Hybrid Gold Open Access | P21: Scopus | Q21: 2-s2.0-85116415765 | R21: =COUNTIF( Papers!G:G, RAW_DATA!Q21 ) = 0 -> FALSE | S21: =(COUNTIF(B:B, B21) > 1 ) -> FALSE
A22: Bedué P.; Fritzsche A. | B22: Can we trust AI? An empirical investigation of trust requirements and guide to successful AI adoption | C22: 2022 | D22: Journal of Enterprise Information Management | E22: 35 | F22: 2 | H22: 530 | I22: 549 | J22: 250 | K22: 10.1108/JEIM-06-2020-0233 | L22: https://www.scopus.com/pages/publications/85106282628?origin=resultslist | M22: Article | N22: Final | P22: Scopus | Q22: 2-s2.0-85106282628 | R22: =COUNTIF( Papers!G:G, RAW_DATA!Q22 ) = 0 -> FALSE | S22: =(COUNTIF(B:B, B22) > 1 ) -> FALSE
A23: Parent-Rocheleau X.; Parker S.K. | B23: Algorithms as work designers: How algorithmic management influences the design of jobs | C23: 2022 | D23: Human Resource Management Review | E23: 32 | F23: 3 | G23: 100838 | J23: 330 | K23: 10.1016/j.hrmr.2021.100838 | L23: https://www.scopus.com/pages/publications/85105550128?origin=resultslist | M23: Article | N23: Final | O23: All Open Access; Bronze Open Access; Green Open Access | P23: Scopus | Q23: 2-s2.0-85105550128 | R23: =COUNTIF( Papers!G:G, RAW_DATA!Q23 ) = 0 -> FALSE | S23: =(COUNTIF(B:B, B23) > 1 ) -> FALSE
A24: Hayes B.; Shah J.A. | B24: Improving Robot Controller Transparency Through Autonomous Policy Explanation | C24: 2017 | D24: ACM/IEEE International Conference on Human-Robot Interaction | E24: Part F127194 | H24: 303 | I24: 312 | J24: 234 | K24: 10.1145/2909824.3020233 | L24: https://www.scopus.com/pages/publications/85021787797?origin=resultslist | M24: Conference paper | N24: Final | O24: All Open Access; Green Open Access | P24: Scopus | Q24: 2-s2.0-85021787797 | R24: =COUNTIF( Papers!G:G, RAW_DATA!Q24 ) = 0 -> FALSE | S24: =(COUNTIF(B:B, B24) > 1 ) -> FALSE
A25: Dudley J.J.; Kristensson P.O. | B25: A review of user interface design for interactive machine learning | C25: 2018 | D25: ACM Transactions on Interactive Intelligent Systems | E25: 8 | F25: 2 | G25: 8 | J25: 292 | K25: 10.1145/3185517 | L25: https://www.scopus.com/pages/publications/85058625902?origin=resultslist | M25: Review | N25: Final | O25: All Open Access; Green Open Access | P25: Scopus | Q25: 2-s2.0-85058625902 | R25: =COUNTIF( Papers!G:G, RAW_DATA!Q25 ) = 0 -> FALSE | S25: =(COUNTIF(B:B, B25) > 1 ) -> FALSE
A26: Chowdhury S.; Dey P.; Joel-Edgar S.; Bhattacharya S.; Rodriguez-Espindola O.; Abadie A.; Truong L. | B26: Unlocking the value of artificial intelligence in human resource management through AI capability framework | C26: 2023 | D26: Human Resource Management Review | E26: 33 | F26: 1 | G26: 100899 | J26: 719 | K26: 10.1016/j.hrmr.2022.100899 | L26: https://www.scopus.com/pages/publications/85127325455?origin=resultslist | M26: Article | N26: Final | O26: All Open Access; Green Open Access | P26: Scopus | Q26: 2-s2.0-85127325455 | R26: =COUNTIF( Papers!G:G, RAW_DATA!Q26 ) = 0 -> FALSE | S26: =(COUNTIF(B:B, B26) > 1 ) -> FALSE
A27: Chiou E.K.; Lee J.D. | B27: Trusting Automation: Designing for Responsivity and Resilience | C27: 2023 | D27: Human Factors | E27: 65 | F27: 1 | H27: 137 | I27: 165 | J27: 234 | K27: 10.1177/00187208211009995 | L27: https://www.scopus.com/pages/publications/85104981249?origin=resultslist | M27: Article | N27: Final | P27: Scopus | Q27: 2-s2.0-85104981249 | R27: =COUNTIF( Papers!G:G, RAW_DATA!Q27 ) = 0 -> FALSE | S27: =(COUNTIF(B:B, B27) > 1 ) -> FALSE
A28: Liu K.; Tao D. | B28: The roles of trust, personalization, loss of privacy, and anthropomorphism in public acceptance of smart healthcare services | C28: 2022 | D28: Computers in Human Behavior | E28: 127 | G28: 107026 | J28: 363 | K28: 10.1016/j.chb.2021.107026 | L28: https://www.scopus.com/pages/publications/85115048327?origin=resultslist | M28: Article | N28: Final | P28: Scopus | Q28: 2-s2.0-85115048327 | R28: =COUNTIF( Papers!G:G, RAW_DATA!Q28 ) = 0 -> FALSE | S28: =(COUNTIF(B:B, B28) > 1 ) -> FALSE
A29: Yam K.C.; Tang P.M.; Jackson J.C.; Su R.; Gray K. | B29: The Rise of Robots Increases Job Insecurity and Maladaptive Workplace Behaviors: Multimethod Evidence | C29: 2022 | D29: Journal of Applied Psychology | E29: 108 | F29: 5 | H29: 850 | I29: 870 | J29: 244 | K29: 10.1037/apl0001045 | L29: https://www.scopus.com/pages/publications/85140762473?origin=resultslist | M29: Article | N29: Final | P29: Scopus | Q29: 2-s2.0-85140762473 | R29: =COUNTIF( Papers!G:G, RAW_DATA!Q29 ) = 0 -> FALSE | S29: =(COUNTIF(B:B, B29) > 1 ) -> FALSE
A30: Kohn S.C.; de Visser E.J.; Wiese E.; Lee Y.-C.; Shaw T.H. | B30: Measurement of Trust in Automation: A Narrative Review and Reference Guide | C30: 2021 | D30: Frontiers in Psychology | E30: 12 | G30: 604977 | J30: 253 | K30: 10.3389/fpsyg.2021.604977 | L30: https://www.scopus.com/pages/publications/85118576621?origin=resultslist | M30: Review | N30: Final | O30: All Open Access; Gold Open Access; Green Open Access | P30: Scopus | Q30: 2-s2.0-85118576621 | R30: =COUNTIF( Papers!G:G, RAW_DATA!Q30 ) = 0 -> FALSE | S30: =(COUNTIF(B:B, B30) > 1 ) -> FALSE
A31: Hengstler M.; Enkel E.; Duelli S. | B31: Applied artificial intelligence and trust-The case of autonomous vehicles and medical assistance devices | C31: 2016 | D31: Technological Forecasting and Social Change | E31: 105 | H31: 105 | I31: 120 | J31: 557 | K31: 10.1016/j.techfore.2015.12.014 | L31: https://www.scopus.com/pages/publications/84957895151?origin=resultslist | M31: Article | N31: Final | P31: Scopus | Q31: 2-s2.0-84957895151 | R31: =COUNTIF( Papers!G:G, RAW_DATA!Q31 ) = 0 -> FALSE | S31: =(COUNTIF(B:B, B31) > 1 ) -> FALSE
A32: Bach T.A.; Khan A.; Hallock H.; Beltrão G.; Sousa S. | B32: A Systematic Literature Review of User Trust in AI-Enabled Systems: An HCI Perspective | C32: 2024 | D32: International Journal of Human-Computer Interaction | E32: 40 | F32: 5 | H32: 1251 | I32: 1266 | J32: 239 | K32: 10.1080/10447318.2022.2138826 | L32: https://www.scopus.com/pages/publications/85141953140?origin=resultslist | M32: Article | N32: Final | O32: All Open Access; Bronze Open Access; Green Open Access | P32: Scopus | Q32: 2-s2.0-85141953140 | R32: =COUNTIF( Papers!G:G, RAW_DATA!Q32 ) = 0 -> FALSE | S32: =(COUNTIF(B:B, B32) > 1 ) -> FALSE
A33: Sun W.; Bocchini P.; Davison B.D. | B33: Applications of artificial intelligence for disaster management | C33: 2020 | D33: Natural Hazards | E33: 103 | F33: 3 | H33: 2631 | I33: 2689 | J33: 376 | K33: 10.1007/s11069-020-04124-3 | L33: https://www.scopus.com/pages/publications/85087516664?origin=resultslist | M33: Review | N33: Final | P33: Scopus | Q33: 2-s2.0-85087516664 | R33: =COUNTIF( Papers!G:G, RAW_DATA!Q33 ) = 0 -> FALSE | S33: =(COUNTIF(B:B, B33) > 1 ) -> FALSE
A34: Glikson E.; Woolley A.W. | B34: Human trust in artificial intelligence: Review of empirical research | C34: 2020 | D34: Academy of Management Annals | E34: 14 | F34: 2 | H34: 627 | I34: 660 | J34: 1836 | K34: 10.5465/annals.2018.0057 | L34: https://www.scopus.com/pages/publications/85087295894?origin=resultslist | M34: Article | N34: Final | P34: Scopus | Q34: 2-s2.0-85087295894 | R34: =COUNTIF( Papers!G:G, RAW_DATA!Q34 ) = 0 -> FALSE | S34: =(COUNTIF(B:B, B34) > 1 ) -> FALSE
A35: Xu Z.; Zhang K.; Min H.; Wang Z.; Zhao X.; Liu P. | B35: What drives people to accept automated vehicles? Findings from a field experiment | C35: 2018 | D35: Transportation Research Part C: Emerging Technologies | E35: 95 | H35: 320 | I35: 334 | J35: 580 | K35: 10.1016/j.trc.2018.07.024 | L35: https://www.scopus.com/pages/publications/85050653532?origin=resultslist | M35: Article | N35: Final | P35: Scopus | Q35: 2-s2.0-85050653532 | R35: =COUNTIF( Papers!G:G, RAW_DATA!Q35 ) = 0 -> FALSE | S35: =(COUNTIF(B:B, B35) > 1 ) -> FALSE
A36: Haleem A.; Javaid M.; Asim Qadri M.; Pratap Singh R.; Suman R. | B36: Artificial intelligence (AI) applications for marketing: A literature-based study | C36: 2022 | D36: International Journal of Intelligent Networks | E36: 3 | H36: 119 | I36: 132 | J36: 738 | K36: 10.1016/j.ijin.2022.08.005 | L36: https://www.scopus.com/pages/publications/85137403442?origin=resultslist | M36: Review | N36: Final | O36: All Open Access; Gold Open Access; Green Open Access | P36: Scopus | Q36: 2-s2.0-85137403442 | R36: =COUNTIF( Papers!G:G, RAW_DATA!Q36 ) = 0 -> FALSE | S36: =(COUNTIF(B:B, B36) > 1 ) -> FALSE
A37: Mathur M.B.; Reichling D.B. | B37: Navigating a social world with robot partners: A quantitative cartography of the Uncanny Valley | C37: 2016 | D37: Cognition | E37: 146 | H37: 22 | I37: 32 | J37: 360 | K37: 10.1016/j.cognition.2015.09.008 | L37: https://www.scopus.com/pages/publications/84942154696?origin=resultslist | M37: Article | N37: Final | O37: All Open Access; Hybrid Gold Open Access | P37: Scopus | Q37: 2-s2.0-84942154696 | R37: =COUNTIF( Papers!G:G, RAW_DATA!Q37 ) = 0 -> FALSE | S37: =(COUNTIF(B:B, B37) > 1 ) -> FALSE
A38: Abdul A.; Vermeulen J.; Wang D.; Lim B.Y.; Kankanhalli M. | B38: Trends and trajectories for explainable, accountable and intelligible systems: An HCI research agenda | C38: 2018 | D38: Conference on Human Factors in Computing Systems - Proceedings | E38: 2018-April | J38: 639 | K38: 10.1145/3173574.3174156 | L38: https://www.scopus.com/pages/publications/85044532871?origin=resultslist | M38: Conference paper | N38: Final | P38: Scopus | Q38: 2-s2.0-85044532871 | R38: =COUNTIF( Papers!G:G, RAW_DATA!Q38 ) = 0 -> FALSE | S38: =(COUNTIF(B:B, B38) > 1 ) -> FALSE
A39: Zhang Y.; Xiong F.; Xie Y.; Fan X.; Gu H. | B39: The Impact of Artificial Intelligence and Blockchain on the Accounting Profession | C39: 2020 | D39: IEEE Access | E39: 8 | G39: 9110603 | H39: 110461 | I39: 110477 | J39: 233 | K39: 10.1109/ACCESS.2020.3000505 | L39: https://www.scopus.com/pages/publications/85087542875?origin=resultslist | M39: Article | N39: Final | O39: All Open Access; Gold Open Access; Green Open Access | P39: Scopus | Q39: 2-s2.0-85087542875 | R39: =COUNTIF( Papers!G:G, RAW_DATA!Q39 ) = 0 -> FALSE | S39: =(COUNTIF(B:B, B39) > 1 ) -> FALSE
A40: Nastjuk I.; Herrenkind B.; Marrone M.; Brendel A.B.; Kolbe L.M. | B40: What drives the acceptance of autonomous driving? An investigation of acceptance factors from an end-user's perspective | C40: 2020 | D40: Technological Forecasting and Social Change | E40: 161 | G40: 120319 | J40: 302 | K40: 10.1016/j.techfore.2020.120319 | L40: https://www.scopus.com/pages/publications/85091505828?origin=resultslist | M40: Article | N40: Final | O40: All Open Access; Hybrid Gold Open Access | P40: Scopus | Q40: 2-s2.0-85091505828 | R40: =COUNTIF( Papers!G:G, RAW_DATA!Q40 ) = 0 -> FALSE | S40: =(COUNTIF(B:B, B40) > 1 ) -> FALSE
...

Sheet Papers
A1: Reference | B1: Authors | C1: Title | D1: Type | E1: Title Screening | F1: Abstract Screening | G1: EID | H1: [Autofilled] DUPLICATE EID | I1: [Autofilled] DUPLICATE TITLE
B2: Stepin I.; Alonso J.M.; Catala A.; Pereira-Farina M. | C2: A Survey of Contrastive and Counterfactual Explanation Generation Methods for Explainable Artificial Intelligence | D2: N/A | E2: Yes | F2: No | G2: =_xlfn.XLOOKUP( C2,RAW_DATA!B:B, RAW_DATA!Q:Q, "NOT FOUND" ) -> 2-s2.0-85099601493 | H2: =COUNTIF( G:G, G2 ) > 1 -> FALSE | I2: =COUNTIF( C:C, C2 ) > 1 -> FALSE
A3: nazar_hci_xai_healthcare | B3: Nazar M.; Alam M.M.; Yafi E.; Su'Ud M.M. | C3: A Systematic Review of Human-Computer Interaction and Explainable Artificial Intelligence in Healthcare with Artificial Intelligence Techniques | D3: Theoretical | E3: Yes | F3: Yes | G3: =_xlfn.XLOOKUP( C3,RAW_DATA!B:B, RAW_DATA!Q:Q, "NOT FOUND" ) -> 2-s2.0-85119430656 | H3: =COUNTIF( G:G, G3 ) > 1 -> FALSE | I3: =COUNTIF( C:C, C3 ) > 1 -> FALSE
A4: young_patient_systematic_review | B4: Young A.T.; Amara D.; Bhattacharya A.; Wei M.L. | C4: Patient and general public attitudes towards clinical artificial intelligence: a mixed methods systematic review | D4: Theoretical | E4: Yes | F4: Yes | G4: =_xlfn.XLOOKUP( C4,RAW_DATA!B:B, RAW_DATA!Q:Q, "NOT FOUND" ) -> 2-s2.0-85115041953 | H4: =COUNTIF( G:G, G4 ) > 1 -> FALSE | I4: =COUNTIF( C:C, C4 ) > 1 -> FALSE
B5: Rashid A.B.; Kausik M.A.K. | C5: AI revolutionizing industries worldwide: A comprehensive overview of its diverse applications | D5: N/A | E5: Yes | F5: No | G5: =_xlfn.XLOOKUP( C5,RAW_DATA!B:B, RAW_DATA!Q:Q, "NOT FOUND" ) -> 2-s2.0-85204730281 | H5: =COUNTIF( G:G, G5 ) > 1 -> FALSE | I5: =COUNTIF( C:C, C5 ) > 1 -> FALSE
A6: Tong_artificial_intelligence_feedback | B6: Tong S.; Jia N.; Luo X.; Fang Z. | C6: The Janus face of artificial intelligence feedback: Deployment versus disclosure effects on employee performance | D6: Theoretical | E6: Yes | F6: Yes | G6: =_xlfn.XLOOKUP( C6,RAW_DATA!B:B, RAW_DATA!Q:Q, "NOT FOUND" ) -> 2-s2.0-85109705359 | H6: =COUNTIF( G:G, G6 ) > 1 -> FALSE | I6: =COUNTIF( C:C, C6 ) > 1 -> FALSE
A7: zhang_automated_vehicle_acceptance | B7: Zhang T.; Tao D.; Qu X.; Zhang X.; Zeng J.; Zhu H.; Zhu H. | C7: Automated vehicle acceptance in China: Social influence and initial trust are key determinants | D7: Empirical | E7: Yes | F7: Yes | G7: =_xlfn.XLOOKUP( C7,RAW_DATA!B:B, RAW_DATA!Q:Q, "NOT FOUND" ) -> 2-s2.0-85078934939 | H7: =COUNTIF( G:G, G7 ) > 1 -> FALSE | I7: =COUNTIF( C:C, C7 ) > 1 -> FALSE
A8: tussyadiah_do_travelers_trust | B8: Tussyadiah I.P.; Zach F.J.; Wang J. | C8: Do travelers trust intelligent service robots? | D8: Practical | E8: Yes | F8: Yes | G8: =_xlfn.XLOOKUP( C8,RAW_DATA!B:B, RAW_DATA!Q:Q, "NOT FOUND" ) -> 2-s2.0-85079861440 | H8: =COUNTIF( G:G, G8 ) > 1 -> FALSE | I8: =COUNTIF( C:C, C8 ) > 1 -> FALSE
B9: Rudin C.; Chen C.; Chen Z.; Huang H.; Semenova L.; Zhong C. | C9: Interpretable machine learning: Fundamental principles and 10 grand challenges | E9: No | F9: No | G9: =_xlfn.XLOOKUP( C9,RAW_DATA!B:B, RAW_DATA!Q:Q, "NOT FOUND" ) -> 2-s2.0-85125573696 | H9: =COUNTIF( G:G, G9 ) > 1 -> FALSE | I9: =COUNTIF( C:C, C9 ) > 1 -> FALSE
A10: choudhury_asan_2020_trust_clinicians | B10: Asan O.; Bayrak A.E.; Choudhury A. | C10: Artificial Intelligence and Human Trust in Healthcare: Focus on Clinicians | D10: Theoretical | E10: Yes | F10: Yes | G10: =_xlfn.XLOOKUP( C10,RAW_DATA!B:B, RAW_DATA!Q:Q, "NOT FOUND" ) -> 2-s2.0-85086727009 | H10: =COUNTIF( G:G, G10 ) > 1 -> FALSE | I10: =COUNTIF( C:C, C10 ) > 1 -> FALSE
B11: Hergeth S.; Lorenz L.; Vilimek R.; Krems J.F. | C11: Keep Your Scanners Peeled: Gaze Behavior as a Measure of Automation Trust during Highly Automated Driving | D11: N/A | E11: Yes | F11: No | G11: =_xlfn.XLOOKUP( C11,RAW_DATA!B:B, RAW_DATA!Q:Q, "NOT FOUND" ) -> 2-s2.0-84962910809 | H11: =COUNTIF( G:G, G11 ) > 1 -> FALSE | I11: =COUNTIF( C:C, C11 ) > 1 -> FALSE
B12: Honig S.; Oron-Gilad T. | C12: Understanding and resolving failures in human-robot interaction: Literature review and model development | E12: No | F12: No | G12: =_xlfn.XLOOKUP( C12,RAW_DATA!B:B, RAW_DATA!Q:Q, "NOT FOUND" ) -> 2-s2.0-85048531596 | H12: =COUNTIF( G:G, G12 ) > 1 -> FALSE | I12: =COUNTIF( C:C, C12 ) > 1 -> FALSE
A13: carsten_hmi_automated_cars | B13: Carsten O.; Martens M.H. | C13: How can humans understand their automated cars? HMI principles, problems and solutions | D13: Theoretical | E13: Yes | F13: Yes | G13: =_xlfn.XLOOKUP( C13,RAW_DATA!B:B, RAW_DATA!Q:Q, "NOT FOUND" ) -> 2-s2.0-85046726952 | H13: =COUNTIF( G:G, G13 ) > 1 -> FALSE | I13: =COUNTIF( C:C, C13 ) > 1 -> FALSE
A14: vilone_longo_2021 | B14: Vilone G.; Longo L. | C14: Notions of explainability and evaluation approaches for explainable artificial intelligence | D14: Theoretical | E14: Yes | F14: Yes | G14: =_xlfn.XLOOKUP( C14,RAW_DATA!B:B, RAW_DATA!Q:Q, "NOT FOUND" ) -> 2-s2.0-85107637272 | H14: =COUNTIF( G:G, G14 ) > 1 -> FALSE | I14: =COUNTIF( C:C, C14 ) > 1 -> FALSE
B15: Pereira V.; Hadjielias E.; Christofi M.; Vrontis D. | C15: A systematic literature review on the impact of artificial intelligence on workplace outcomes: A multi-process perspective | E15: No | F15: No | G15: =_xlfn.XLOOKUP( C15,RAW_DATA!B:B, RAW_DATA!Q:Q, "NOT FOUND" ) -> 2-s2.0-85114687655 | H15: =COUNTIF( G:G, G15 ) > 1 -> FALSE | I15: =COUNTIF( C:C, C15 ) > 1 -> FALSE
B16: Langer M.; Oster D.; Speith T.; Hermanns H.; Kästner L.; Schmidt E.; Sesing A.; Baum K. | C16: What do we want from Explainable Artificial Intelligence (XAI)? – A stakeholder perspective on XAI and a conceptual model guiding interdisciplinary XAI research | E16: No | F16: No | G16: =_xlfn.XLOOKUP( C16,RAW_DATA!B:B, RAW_DATA!Q:Q, "NOT FOUND" ) -> 2-s2.0-85101531468 | H16: =COUNTIF( G:G, G16 ) > 1 -> FALSE | I16: =COUNTIF( C:C, C16 ) > 1 -> FALSE
B17: Chalmers D.; MacKenzie N.G.; Carter S. | C17: Artificial Intelligence and Entrepreneurship: Implications for Venture Creation in the Fourth Industrial Revolution | E17: Yes | F17: No | G17: =_xlfn.XLOOKUP( C17,RAW_DATA!B:B, RAW_DATA!Q:Q, "NOT FOUND" ) -> 2-s2.0-85087930775 | H17: =COUNTIF( G:G, G17 ) > 1 -> FALSE | I17: =COUNTIF( C:C, C17 ) > 1 -> FALSE
B18: Chowdhury S.; Budhwar P.; Dey P.K.; Joel-Edgar S.; Abadie A. | C18: AI-employee collaboration and business performance: Integrating knowledge-based view, socio-technical systems and organisational socialisation framework | E18: No | F18: No | G18: =_xlfn.XLOOKUP( C18,RAW_DATA!B:B, RAW_DATA!Q:Q, "NOT FOUND" ) -> 2-s2.0-85124046364 | H18: =COUNTIF( G:G, G18 ) > 1 -> FALSE | I18: =COUNTIF( C:C, C18 ) > 1 -> FALSE
B19: Dellermann D.; Ebel P.; Söllner M.; Leimeister J.M. | C19: Hybrid Intelligence | E19: No | F19: No | G19: =_xlfn.XLOOKUP( C19,RAW_DATA!B:B, RAW_DATA!Q:Q, "NOT FOUND" ) -> 2-s2.0-85069455009 | H19: =COUNTIF( G:G, G19 ) > 1 -> FALSE | I19: =COUNTIF( C:C, C19 ) > 1 -> FALSE
B20: Man Tang P.; Koopman J.; McClean S.T.; Zhang J.H.; Hon Li C.; de Cremer D.; Lu Y.; Stewart Ng C.T. | C20: WHEN CONSCIENTIOUS EMPLOYEES MEET INTELLIGENT MACHINES: AN INTEGRATIVE APPROACH INSPIRED BY COMPLEMENTARITY THEORY AND ROLE THEORY | E20: No | F20: No | G20: =_xlfn.XLOOKUP( C20,RAW_DATA!B:B, RAW_DATA!Q:Q, "NOT FOUND" ) -> 2-s2.0-85135124659 | H20: =COUNTIF( G:G, G20 ) > 1 -> FALSE | I20: =COUNTIF( C:C, C20 ) > 1 -> FALSE
B21: Mirbabaie M.; Brünker F.; Möllmann Frick N.R.J.; Stieglitz S. | C21: The rise of artificial intelligence – understanding the AI identity threat at the workplace | E21: No | F21: No | G21: =_xlfn.XLOOKUP( C21,RAW_DATA!B:B, RAW_DATA!Q:Q, "NOT FOUND" ) -> 2-s2.0-85116415765 | H21: =COUNTIF( G:G, G21 ) > 1 -> FALSE | I21: =COUNTIF( C:C, C21 ) > 1 -> FALSE
B22: Bedué P.; Fritzsche A. | C22: Can we trust AI? An empirical investigation of trust requirements and guide to successful AI adoption | E22: No | F22: No | G22: =_xlfn.XLOOKUP( C22,RAW_DATA!B:B, RAW_DATA!Q:Q, "NOT FOUND" ) -> 2-s2.0-85106282628 | H22: =COUNTIF( G:G, G22 ) > 1 -> FALSE | I22: =COUNTIF( C:C, C22 ) > 1 -> FALSE
B23: Parent-Rocheleau X.; Parker S.K. | C23: Algorithms as work designers: How algorithmic management influences the design of jobs | E23: No | F23: No | G23: =_xlfn.XLOOKUP( C23,RAW_DATA!B:B, RAW_DATA!Q:Q, "NOT FOUND" ) -> 2-s2.0-85105550128 | H23: =COUNTIF( G:G, G23 ) > 1 -> FALSE | I23: =COUNTIF( C:C, C23 ) > 1 -> FALSE
B24: Hayes B.; Shah J.A. | C24: Improving Robot Controller Transparency Through Autonomous Policy Explanation | E24: No | F24: No | G24: =_xlfn.XLOOKUP( C24,RAW_DATA!B:B, RAW_DATA!Q:Q, "NOT FOUND" ) -> 2-s2.0-85021787797 | H24: =COUNTIF( G:G, G24 ) > 1 -> FALSE | I24: =COUNTIF( C:C, C24 ) > 1 -> FALSE
A25: hayes2017improving | B25: Dudley J.J.; Kristensson P.O. | C25: A review of user interface design for interactive machine learning | D25: Empirical | E25: Yes | F25: Yes | G25: =_xlfn.XLOOKUP( C25,RAW_DATA!B:B, RAW_DATA!Q:Q, "NOT FOUND" ) -> 2-s2.0-85058625902 | H25: =COUNTIF( G:G, G25 ) > 1 -> FALSE | I25: =COUNTIF( C:C, C25 ) > 1 -> FALSE
B26: Chowdhury S.; Dey P.; Joel-Edgar S.; Bhattacharya S.; Rodriguez-Espindola O.; Abadie A.; Truong L. | C26: Unlocking the value of artificial intelligence in human resource management through AI capability framework | E26: No | F26: No | G26: =_xlfn.XLOOKUP( C26,RAW_DATA!B:B, RAW_DATA!Q:Q, "NOT FOUND" ) -> 2-s2.0-85127325455 | H26: =COUNTIF( G:G, G26 ) > 1 -> FALSE | I26: =COUNTIF( C:C, C26 ) > 1 -> FALSE
B27: Chiou E.K.; Lee J.D. | C27: Trusting Automation: Designing for Responsivity and Resilience | E27: No | F27: No | G27: =_xlfn.XLOOKUP( C27,RAW_DATA!B:B, RAW_DATA!Q:Q, "NOT FOUND" ) -> 2-s2.0-85104981249 | H27: =COUNTIF( G:G, G27 ) > 1 -> FALSE | I27: =COUNTIF( C:C, C27 ) > 1 -> FALSE
B28: Liu K.; Tao D. | C28: The roles of trust, personalization, loss of privacy, and anthropomorphism in public acceptance of smart healthcare services | E28: No | F28: No | G28: =_xlfn.XLOOKUP( C28,RAW_DATA!B:B, RAW_DATA!Q:Q, "NOT FOUND" ) -> 2-s2.0-85115048327 | H28: =COUNTIF( G:G, G28 ) > 1 -> FALSE | I28: =COUNTIF( C:C, C28 ) > 1 -> FALSE
A29: chiou_trusting_automation | B29: Yam K.C.; Tang P.M.; Jackson J.C.; Su R.; Gray K. | C29: The Rise of Robots Increases Job Insecurity and Maladaptive Workplace Behaviors: Multimethod Evidence | D29: Theoretical | E29: Yes | F29: Yes | G29: =_xlfn.XLOOKUP( C29,RAW_DATA!B:B, RAW_DATA!Q:Q, "NOT FOUND" ) -> 2-s2.0-85140762473 | H29: =COUNTIF( G:G, G29 ) > 1 -> FALSE | I29: =COUNTIF( C:C, C29 ) > 1 -> FALSE
B30: Kohn S.C.; de Visser E.J.; Wiese E.; Lee Y.-C.; Shaw T.H. | C30: Measurement of Trust in Automation: A Narrative Review and Reference Guide | E30: Yes | F30: No | G30: =_xlfn.XLOOKUP( C30,RAW_DATA!B:B, RAW_DATA!Q:Q, "NOT FOUND" ) -> 2-s2.0-85118576621 | H30: =COUNTIF( G:G, G30 ) > 1 -> FALSE | I30: =COUNTIF( C:C, C30 ) > 1 -> FALSE
B31: Hengstler M.; Enkel E.; Duelli S. | C31: Applied artificial intelligence and trust-The case of autonomous vehicles and medical assistance devices | E31: No | F31: No | G31: =_xlfn.XLOOKUP( C31,RAW_DATA!B:B, RAW_DATA!Q:Q, "NOT FOUND" ) -> 2-s2.0-84957895151 | H31: =COUNTIF( G:G, G31 ) > 1 -> FALSE | I31: =COUNTIF( C:C, C31 ) > 1 -> FALSE
A32: john_measurement_of_trust | B32: Bach T.A.; Khan A.; Hallock H.; Beltrão G.; Sousa S. | C32: A Systematic Literature Review of User Trust in AI-Enabled Systems: An HCI Perspective | D32: Theoretical | E32: Yes | F32: Yes | G32: =_xlfn.XLOOKUP( C32,RAW_DATA!B:B, RAW_DATA!Q:Q, "NOT FOUND" ) -> 2-s2.0-85141953140 | H32: =COUNTIF( G:G, G32 ) > 1 -> FALSE | I32: =COUNTIF( C:C, C32 ) > 1 -> FALSE
B33: Sun W.; Bocchini P.; Davison B.D. | C33: Applications of artificial intelligence for disaster management | E33: Yes | F33: No | G33: =_xlfn.XLOOKUP( C33,RAW_DATA!B:B, RAW_DATA!Q:Q, "NOT FOUND" ) -> 2-s2.0-85087516664 | H33: =COUNTIF( G:G, G33 ) > 1 -> FALSE | I33: =COUNTIF( C:C, C33 ) > 1 -> FALSE
B34: Glikson E.; Woolley A.W. | C34: Human trust in artificial intelligence: Review of empirical research | E34: Yes | F34: No | G34: =_xlfn.XLOOKUP( C34,RAW_DATA!B:B, RAW_DATA!Q:Q, "NOT FOUND" ) -> 2-s2.0-85087295894 | H34: =COUNTIF( G:G, G34 ) > 1 -> FALSE | I34: =COUNTIF( C:C, C34 ) > 1 -> FALSE
A35: bach_systematic_literature_review | B35: Xu Z.; Zhang K.; Min H.; Wang Z.; Zhao X.; Liu P. | C35: What drives people to accept automated vehicles? Findings from a field experiment | D35: Empirical | E35: Yes | F35: Yes | G35: =_xlfn.XLOOKUP( C35,RAW_DATA!B:B, RAW_DATA!Q:Q, "NOT FOUND" ) -> 2-s2.0-85050653532 | H35: =COUNTIF( G:G, G35 ) > 1 -> FALSE | I35: =COUNTIF( C:C, C35 ) > 1 -> FALSE
B36: Haleem A.; Javaid M.; Asim Qadri M.; Pratap Singh R.; Suman R. | C36: Artificial intelligence (AI) applications for marketing: A literature-based study | E36: No | F36: No | G36: =_xlfn.XLOOKUP( C36,RAW_DATA!B:B, RAW_DATA!Q:Q, "NOT FOUND" ) -> 2-s2.0-85137403442 | H36: =COUNTIF( G:G, G36 ) > 1 -> FALSE | I36: =COUNTIF( C:C, C36 ) > 1 -> FALSE
A37: glickson_2020_review_of_empirical_research | B37: Mathur M.B.; Reichling D.B. | C37: Navigating a social world with robot partners: A quantitative cartography of the Uncanny Valley | D37: Theoretical | E37: Yes | F37: Yes | G37: =_xlfn.XLOOKUP( C37,RAW_DATA!B:B, RAW_DATA!Q:Q, "NOT FOUND" ) -> 2-s2.0-84942154696 | H37: =COUNTIF( G:G, G37 ) > 1 -> FALSE | I37: =COUNTIF( C:C, C37 ) > 1 -> FALSE
B38: Abdul A.; Vermeulen J.; Wang D.; Lim B.Y.; Kankanhalli M. | C38: Trends and trajectories for explainable, accountable and intelligible systems: An HCI research agenda | E38: Yes | F38: No | G38: =_xlfn.XLOOKUP( C38,RAW_DATA!B:B, RAW_DATA!Q:Q, "NOT FOUND" ) -> 2-s2.0-85044532871 | H38: =COUNTIF( G:G, G38 ) > 1 -> FALSE | I38: =COUNTIF( C:C, C38 ) > 1 -> FALSE
B39: Zhang Y.; Xiong F.; Xie Y.; Fan X.; Gu H. | C39: The Impact of Artificial Intelligence and Blockchain on the Accounting Profession | E39: No | F39: No | G39: =_xlfn.XLOOKUP( C39,RAW_DATA!B:B, RAW_DATA!Q:Q, "NOT FOUND" ) -> 2-s2.0-85087542875 | H39: =COUNTIF( G:G, G39 ) > 1 -> FALSE | I39: =COUNTIF( C:C, C39 ) > 1 -> FALSE
B40: Nastjuk I.; Herrenkind B.; Marrone M.; Brendel A.B.; Kolbe L.M. | C40: What drives the acceptance of autonomous driving? An investigation of acceptance factors from an end-user's perspective | E40: No | F40: No | G40: =_xlfn.XLOOKUP( C40,RAW_DATA!B:B, RAW_DATA!Q:Q, "NOT FOUND" ) -> 2-s2.0-85091505828 | H40: =COUNTIF( G:G, G40 ) > 1 -> FALSE | I40: =COUNTIF( C:C, C40 ) > 1 -> FALSE
...

Sheet Codes
B1: Reference | C1: Factor | D1: Layer | E1: Subdivision | F1: Interpretation | G1: [Autofilled] Valid Reference?
B2: jacovi_2021_formalizing_trust_ai | C2: Warranted Trust (Calibration) | D2: Adaptive Trust Dynamics | E2: Calibration | F2: Alignment between perceived and actual trustworthiness | G2: =IF( COUNTIF( Papers!A:A, B2 ) > 0, "OK", "KO" ) -> OK
B3: carsten_hmi_automated_cars | C3: Calibration | D3: Adaptive Trust Dynamics | E3: Calibration | F3: Understanding system capabilities for correct reliance | G3: =IF( COUNTIF( Papers!A:A, B3 ) > 0, "OK", "KO" ) -> OK
B4: de_visser_longitudinal_trust | C4: Feedback loop | D4: Adaptive Trust Dynamics | E4: Feedback | F4: Outcomes influence future trust | G4: =IF( COUNTIF( Papers!A:A, B4 ) > 0, "OK", "KO" ) -> OK
B5: wang2019artificial | C5: Continuous learning | D5: Adaptive Trust Dynamics | E5: Learning | F5: System adapts over time | G5: =IF( COUNTIF( Papers!A:A, B5 ) > 0, "OK", "KO" ) -> OK
B6: wang2019artificial | C6: Evolution | D6: Adaptive Trust Dynamics | E6: Learning | F6: System evolves and improves performance | G6: =IF( COUNTIF( Papers!A:A, B6 ) > 0, "OK", "KO" ) -> OK
B7: vereschak2021evaluate | C7: Static vs. Dynamic Trust | D7: Adaptive Trust Dynamics | E7: Temporal Evolution | F7: Trust changes over time through interaction | G7: =IF( COUNTIF( Papers!A:A, B7 ) > 0, "OK", "KO" ) -> OK
B8: schepman_general_attitude | C8: Trust Transfer | D8: Adaptive Trust Dynamics | E8: Transfer Mechanism | F8: Process by which trust in humans extends to AI systems they design | G8: =IF( COUNTIF( Papers!A:A, B8 ) > 0, "OK", "KO" ) -> OK
B9: choudhury_chat_gpt | C9: Mediation (Trust → Intent → Use) | D9: Adaptive Trust Dynamics | E9: Temporal Evolution | F9: Process where intent to use mediates the effect of trust on actual usage behavior | G9: =IF( COUNTIF( Papers!A:A, B9 ) > 0, "OK", "KO" ) -> OK
B10: glickson_2020_review_of_empirical_research | C10: Task Characteristics | D10: Context | E10: Task | F10: Trust varies depending on task type | G10: =IF( COUNTIF( Papers!A:A, B10 ) > 0, "OK", "KO" ) -> OK
B11: jacovi_2021_formalizing_trust_ai | C11: Vulnerability / Risk | D11: Context | E11: Risk | F11: Trust involves exposure to potential failure | G11: =IF( COUNTIF( Papers!A:A, B11 ) > 0, "OK", "KO" ) -> OK
B12: de_visser_longitudinal_trust | C12: Vulnerability / Risk | D12: Context | E12: Risk | F12: Trust involves exposure to potential failure | G12: =IF( COUNTIF( Papers!A:A, B12 ) > 0, "OK", "KO" ) -> OK
B13: young_patient_systematic_review | C13: Human in the loop | D13: Context | E13: Environment | F13: Presence of human oversight | G13: =IF( COUNTIF( Papers!A:A, B13 ) > 0, "OK", "KO" ) -> OK
... B80: Tong_artificial_intelligence_feedback | C80: Perceived Empathy | D80: Subjective Perception | E80: Social Perception | F80: Perceived ability of the AI to understand human emotional and contextual nuances. | G80: =IF( COUNTIF( Papers!A:A, B80 ) > 0, "OK", "KO" ) -> OK

Sheet Statistics
B4: Total Papers | D4: =COUNTA( Papers!C:C ) - 1 -> 599
D6: Count | E6: Perc
B7: TITLE | C7: PASS | D7: =COUNTIF( Papers!E:E, "Yes" ) -> 266 | E7: =D7/$D$4 -> 0.44407346 | G7: Empirical
C8: FAIL | D8: =COUNTIF( Papers!E:E, "No" ) -> 333 | E8: =D8/$D$4 -> 0.55592654 | G8: Theoretical
C9: Checksum | D9: =IF(SUM(D7:D8)=$D$4,"OK","KO") -> OK | G9: Practical
B10: ABSTRACT (Absolute) | C10: PASS | D10: =COUNTIF( Papers!F:F, "Yes" ) -> 47 | E10: =D10/$D$4 -> 0.078464107
C11: FAIL | D11: =COUNTIF( Papers!F:F, "No" ) -> 552 | E11: =D11/$D$4 -> 0.92153589
C12: Checksum | D12: =IF(SUM(D10:D11)=$D$4,"OK","KO") -> OK
B13: ABSTRACT (Relative) | C13: PASS | D13: =COUNTIFS( Papers!E:E, "Yes", Papers!F:F, "Yes" ) -> 47 | E13: =D13/$D$7 -> 0.17669173
C14: FAIL | D14: =COUNTIFS( Papers!E:E, "Yes", Papers!F:F, "No" ) -> 219 | E14: =D14/$D$7 -> 0.82330827
C15: Checksum | D15: =IF(SUM(D13:D14)=$D$7,"OK","KO") -> OK
C18: Total selected Empirical | D18: =COUNTIFS( Papers!F:F, "Yes", Papers!D:D, G7 ) -> 24 | E18: =D18/$D$10 -> 0.5106383
C19: Total selected Theoretical | D19: =COUNTIFS( Papers!F:F, "Yes", Papers!D:D, G8 ) -> 22 | E19: =D19/$D$10 -> 0.46808511
C20: Total selected Practical | D20: =COUNTIFS( Papers!F:F, "Yes", Papers!D:D, G9 ) -> 1 | E20: =D20/$D$10 -> 0.021276596
C21: Checksum | D21: =IF(SUM(D18:D20)=D10,"OK","KO") -> OK

Sheet Query
B2: "trust in artificial intelligence" OR "trust in automation" OR "trust calibration" AND ( LIMIT-TO ( DOCTYPE , "ar" ) OR LIMIT-TO ( DOCTYPE , "cp" ) OR LIMIT-TO ( DOCTYPE , "re" ) OR LIMIT-TO ( DOCTYPE , "ch" ) OR LIMIT-TO ( DOCTYPE , "cr" ) OR LIMIT-TO ( DOCTYPE , "sh" ) ) AND ( LIMIT-TO ( LANGUAGE , "English" ) ) AND PUBYEAR > 2015 AND PUBYEAR < 2026
